Workbook

Sheet 입출고현황_백업
B2: ■ 구매자재팀 입출고 현황표
J3: 입고수량 | P3: 출고수량
J4: =SUBTOTAL(9,J7:J1048576) -> 42063 | P4: =SUBTOTAL(9,P7:P1048576) -> 4970
B5: 입고 | N5: 출고
B6: NO | C6: 구분 | D6: 사급 | E6: NEW | F6: 업체 | G6: 담당자 | H6: 품번 | I6: 품명 | J6: 수량 | K6: REV | L6: 위치 | M6: 일자 | N6: 담당자 | O6: 예약번호 | P6: 출고수량 | Q6: 출고일 | R6: 잔여수량
B7: 261 | C7: 가용재고 | E7: 기초 | H7: RA-08M-1887 | I7: =VLOOKUP(H7,위치!B:C,2,0) -> RA-08M-1887]FRM Bas CEPH (VW) | J7: 0 | L7: =VLOOKUP(H7,위치!B:D,3,0) -> E4-2 | M7: 46232 | R7: =J7-P7 -> 0
B8: 195 | C8: 가용재고 | E8: 기초 | H8: RA-08M-2677 | I8: =VLOOKUP(H8,위치!B:C,2,0) -> RA-08M-2677]DRUM SCAN CEPH HEADREST (VW) | J8: 0 | L8: =VLOOKUP(H8,위치!B:D,3,0) -> E2-2 | M8: 46232 | R8: =J8-P8 -> 0
B9: 196 | C9: 가용재고 | E9: 기초 | H9: RA-08M-2679 | I9: =VLOOKUP(H9,위치!B:C,2,0) -> RA-08M-2679]SHAFT CEPH AXIS BODY (VW) | J9: 0 | L9: =VLOOKUP(H9,위치!B:D,3,0) -> E1-2 | M9: 46232 | R9: =J9-P9 -> 0
B10: 197 | C10: 가용재고 | E10: 기초 | H10: RA-08M-2705 | I10: =VLOOKUP(H10,위치!B:C,2,0) -> RA-08M-2705]BLK CEPH AXIS BODY TOP (VW) | J10: 0 | L10: =VLOOKUP(H10,위치!B:D,3,0) -> E1-2 | M10: 46232 | R10: =J10-P10 -> 0
B11: 199 | C11: 가용재고 | E11: 기초 | H11: RA-08M-2707 | I11: =VLOOKUP(H11,위치!B:C,2,0) -> RA-08M-2707]BLK CEPH AXIS BODY REAR (VW) | J11: 0 | L11: =VLOOKUP(H11,위치!B:D,3,0) -> E1-2 | M11: 46232 | R11: =J11-P11 -> 0
B12: 263 | C12: 가용재고 | E12: 기초 | H12: RA-08M-2673 | I12: =VLOOKUP(H12,위치!B:C,2,0) -> RA-08M-2673]BRK CEPH AXIS BODY (VW) | J12: 0 | L12: =VLOOKUP(H12,위치!B:D,3,0) -> E2-2 | M12: 46232 | R12: =J12-P12 -> 0
B13: 169 | C13: 가용재고 | H13: RF-01B-5073 | I13: =VLOOKUP(H13,위치!B:C,2,0) -> RF-01B-5073]DMD FPC Cable | J13: 1 | L13: =VLOOKUP(H13,위치!B:D,3,0) -> A5-3 | M13: 46226 | R13: =J13-P13 -> 1
B14: 306 | C14: 가용재고 | H14: RA-08T-0177 | I14: =VLOOKUP(H14,위치!B:C,2,0) -> 0 | J14: 1 | L14: =VLOOKUP(H14,위치!B:D,3,0) -> S | M14: 46232 | R14: =J14-P14 -> 1
B15: 311 | C15: 가용재고 | H15: RA-08M-0623 | I15: =VLOOKUP(H15,위치!B:C,2,0) -> RA-08M-0623]PIN STOPPER | J15: 1 | L15: =VLOOKUP(H15,위치!B:D,3,0) -> E2-1 | M15: 46232 | R15: =J15-P15 -> 1
B16: 188 | C16: 가용재고 | H16: RF-01H-5052 | I16: =VLOOKUP(H16,위치!B:C,2,0) -> RF-01H-5052]USB TO SBC HARNESS | J16: 2 | L16: =VLOOKUP(H16,위치!B:D,3,0) -> 3S3-4 | M16: 46230 | R16: =J16-P16 -> 2
B17: 190 | C17: 가용재고 | H17: RF-01H-5054 | I17: =VLOOKUP(H17,위치!B:C,2,0) -> RF-01H-5054]DLP Power harness | J17: 2 | L17: =VLOOKUP(H17,위치!B:D,3,0) -> 3S3-4 | M17: 46230 | R17: =J17-P17 -> 2
B18: 153 | C18: 가용재고 | H18: RF-01H-5069 | I18: =VLOOKUP(H18,위치!B:C,2,0) -> RF-01H-5069]LED_Bottom harness | J18: 3 | L18: =VLOOKUP(H18,위치!B:D,3,0) -> 3S3-5 | M18: 46224 | R18: =J18-P18 -> 3
B19: 191 | C19: 가용재고 | H19: RF-01H-5055 | I19: =VLOOKUP(H19,위치!B:C,2,0) -> RF-01H-5055]LED Power harness | J19: 3 | L19: =VLOOKUP(H19,위치!B:D,3,0) -> 3S3-4 | M19: 46230 | R19: =J19-P19 -> 3
B20: 300 | C20: 가용재고 | H20: RA-08A-0611 | I20: =VLOOKUP(H20,위치!B:C,2,0) -> RA-08A-0611]ASM EARLOD Mdl | J20: 3 | L20: =VLOOKUP(H20,위치!B:D,3,0) -> E1-6 | M20: 46232 | R20: =J20-P20 -> 3
B21: 157 | C21: 가용재고 | H21: RF-01T-0354 | I21: =VLOOKUP(H21,위치!B:C,2,0) -> RF-01T-0354]CAMERA CASE L | J21: 4 | L21: =VLOOKUP(H21,위치!B:D,3,0) -> 3E9 | M21: 46224 | R21: =J21-P21 -> 4
B22: 189 | C22: 가용재고 | H22: RF-01H-5053 | I22: =VLOOKUP(H22,위치!B:C,2,0) -> RF-01H-5053]USB to PC harness | J22: 5 | L22: =VLOOKUP(H22,위치!B:D,3,0) -> 3S3-4 | M22: 46230 | R22: =J22-P22 -> 5
B23: 193 | C23: 가용재고 | H23: RF-01H-5067 | I23: =VLOOKUP(H23,위치!B:C,2,0) -> RF-01H-5067]LED_Right harness | J23: 5 | L23: =VLOOKUP(H23,위치!B:D,3,0) -> 3S3-5 | M23: 46230 | R23: =J23-P23 -> 5
B24: 194 | C24: 가용재고 | H24: RF-01H-5075 | I24: =VLOOKUP(H24,위치!B:C,2,0) -> RF-01H-5075] USB to Cal kit harness | J24: 5 | L24: =VLOOKUP(H24,위치!B:D,3,0) -> 3S3-6 | M24: 46230 | R24: =J24-P24 -> 5
... B141: 162 | C141: 가용재고 | H141: RF-09P-0271 | I141: =VLOOKUP(H141,위치!B:C,2,0) -> RF-09P-0271]MIRROR PROTIVE FILM | J141: 1553 | L141: =VLOOKUP(H141,위치!B:D,3,0) -> 3S3-1 | M141: 46224 | R141: =J141-P141 -> 1553
B142: 198 | C142: 출고재고 | E142: 기초 | H142: RA-08M-2706 | I142: =VLOOKUP(H142,위치!B:C,2,0) -> RA-08M-2706]BLK CEPH AXIS BODY FRONT(VW | J142: 7 | L142: =VLOOKUP(H142,위치!B:D,3,0) -> E1-2 | M142: 46232 | N142: 이행찬 | O142: 87119 | P142: 1 | Q142: 46232 | R142: =J142-P142 -> 6
B143: 200 | C143: 출고재고 | E143: 기초 | H143: RA-08M-2708 | I143: =VLOOKUP(H143,위치!B:C,2,0) -> RA-08M-2708]SHAFT CEPH AXIS BODY (VW) | J143: 7 | L143: =VLOOKUP(H143,위치!B:D,3,0) -> E1-2 | M143: 46232 | N143: 이행찬 | O143: 87119 | P143: 1 | Q143: 46232 | R143: =J143-P143 -> 6
B144: 201 | C144: 출고재고 | E144: 기초 | H144: RA-08V-0170 | I144: =VLOOKUP(H144,위치!B:C,2,0) -> RA-08V-0170]CVR MOUNT CEPH ARM | J144: 98 | L144: =VLOOKUP(H144,위치!B:D,3,0) -> E2-3 | M144: 46232 | N144: 이행찬 | O144: 87119 | P144: 1 | Q144: 46232 | R144: =J144-P144 -> 97
B145: 202 | C145: 출고재고 | E145: 기초 | H145: RA-08V-0173 | I145: =VLOOKUP(H145,위치!B:C,2,0) -> RA-08V-0173]DECO CEPH ARM | J145: 91 | L145: =VLOOKUP(H145,위치!B:D,3,0) -> E2-3 | M145: 46232 | N145: 이행찬 | O145: 87119 | P145: 1 | Q145: 46232 | R145: =J145-P145 -> 90
B146: 203 | C146: 출고재고 | E146: 기초 | H146: RA-08V-0181 | I146: =VLOOKUP(H146,위치!B:C,2,0) -> RA-08V-0181]BLK CEPH ARM FIX | J146: 102 | L146: =VLOOKUP(H146,위치!B:D,3,0) -> E2-3 | M146: 46232 | N146: 이행찬 | O146: 87119 | P146: 1 | Q146: 46232 | R146: =J146-P146 -> 101
B147: 205 | C147: 출고재고 | E147: 기초 | H147: RA-08V-0604 | I147: =VLOOKUP(H147,위치!B:C,2,0) -> RA-08V-0604]STOPPER SCAN CEPH | J147: 27 | L147: =VLOOKUP(H147,위치!B:D,3,0) -> E1-3 | M147: 46232 | N147: 이행찬 | O147: 87119 | P147: 1 | Q147: 46232 | R147: =J147-P147 -> 26
B148: 206 | C148: 출고재고 | E148: 기초 | H148: RA-08M-0620 | I148: =VLOOKUP(H148,위치!B:C,2,0) -> RA-08M-0620]PLT CEPH _4HEAD | J148: 99 | L148: =VLOOKUP(H148,위치!B:D,3,0) -> E2-1 | M148: 46232 | N148: 이행찬 | O148: 87119 | P148: 1 | Q148: 46232 | R148: =J148-P148 -> 98
B149: 207 | C149: 출고재고 | E149: 기초 | H149: RA-08V-0621 | I149: =VLOOKUP(H149,위치!B:C,2,0) -> RA-08V-0621]PLT WASHER FIX | J149: 27 | L149: =VLOOKUP(H149,위치!B:D,3,0) -> E1-3 | M149: 46232 | N149: 이행찬 | O149: 87119 | P149: 1 | Q149: 46232 | R149: =J149-P149 -> 26
B150: 208 | C150: 출고재고 | E150: 기초 | H150: RA-08V-0737 | I150: =VLOOKUP(H150,위치!B:C,2,0) -> RA-08V-0737]CVR OC HEADREST BOT | J150: 20 | L150: =VLOOKUP(H150,위치!B:D,3,0) -> F1 | M150: 46232 | N150: 이행찬 | O150: 87119 | P150: 1 | Q150: 46232 | R150: =J150-P150 -> 19
B151: 209 | C151: 출고재고 | E151: 기초 | H151: RA-08V-0974 | I151: =VLOOKUP(H151,위치!B:C,2,0) -> RA-08V-0974]BRK WIRE MOUNT | J151: 21 | L151: =VLOOKUP(H151,위치!B:D,3,0) -> E1-3 | M151: 46232 | N151: 이행찬 | O151: 87119 | P151: 1 | Q151: 46232 | R151: =J151-P151 -> 20
B152: 210 | C152: 출고재고 | E152: 기초 | H152: RA-08V-1872 | I152: =VLOOKUP(H152,위치!B:C,2,0) -> RA-08V-1872]BLK MOUNT OCG SNSR (VW) | J152: 18 | L152: =VLOOKUP(H152,위치!B:D,3,0) -> E2-5 | M152: 46232 | N152: 이행찬 | O152: 87119 | P152: 1 | Q152: 46232 | R152: =J152-P152 -> 17
B153: 211 | C153: 출고재고 | E153: 기초 | H153: RA-08V-2662 | I153: =VLOOKUP(H153,위치!B:C,2,0) -> RA-08V-2662]HOOK CAS CEPH SNSR (R) | J153: 20 | L153: =VLOOKUP(H153,위치!B:D,3,0) -> E2-5 | M153: 46232 | N153: 이행찬 | O153: 87119 | P153: 1 | Q153: 46232 | R153: =J153-P153 -> 19
... B205: 167 | C205: 출고재고 | E205: 기초추가 | H205: RF-01B-5073 | I205: =VLOOKUP(H205,위치!B:C,2,0) -> RF-01B-5073]DMD FPC Cable | J205: 51 | L205: =VLOOKUP(H205,위치!B:D,3,0) -> A5-3 | M205: 46226 | N205: 이행찬 | O205: 84393 | P205: 50 | Q205: 46226 | R205: =J205-P205 -> 1
B206: 138 | C206: 출고재고 | H206: RF-01S-5050 | I206: =VLOOKUP(H206,위치!B:C,2,0) -> RF-01S-5050]TEETH LENS | J206: 123 | L206: =VLOOKUP(H206,위치!B:D,3,0) -> 3L4-2 | M206: 46224 | N206: 이행찬 | O206: 84393 | P206: 50 | Q206: 46226 | R206: =J206-P206 -> 73
B207: 139 | C207: 출고재고 | H207: RF-01M-0268 | I207: =VLOOKUP(H207,위치!B:C,2,0) -> RF-01M-0268]TEETH CAM BLK_HR | J207: 50 | L207: =VLOOKUP(H207,위치!B:D,3,0) -> 3S2-1 | M207: 46224 | N207: 이행찬 | O207: 84393 | P207: 50 | Q207: 46226 | R207: =J207-P207 -> 0
B208: 141 | C208: 출고재고 | H208: RF-01S-5083 | I208: =VLOOKUP(H208,위치!B:C,2,0) -> RF-01S-5083]CAM Trigger_L-R harness | J208: 158 | L208: =VLOOKUP(H208,위치!B:D,3,0) -> 3L3-3 | M208: 46224 | N208: 이행찬 | O208: 84393 | P208: 50 | Q208: 46226 | R208: =J208-P208 -> 108
...

Sheet 현수량 현황표
A1: 구분 | B1: 가용재고
A3: 합계 : 수량
A4: 품번 | B4: 위치 | C4: 요약
A5: C16-635ZZ | C5: 100
A6: RA-01T-1790 | C6: 220
A7: RA-01T-1791 | C7: 348
A8: RA-02A-2008 | C8: 396
A9: RA-02A-2020 | C9: 107
A10: RA-02A-2031 | C10: 117
A11: RA-02A-2280 | C11: 217
A12: RA-02A-2303 | C12: 119
A13: RA-02A-2622 | C13: 423
A14: RA-02A-2711 | C14: 108
A15: RA-02A-2712 | C15: 118
A16: RA-02A-2740 | C16: 0
... A42: RA-03A-0050 | C42: 244
A43: RA-03A-0287 | B43: B1-4 | C43: 28
A44: RA-03A-0314 | C44: 337
A45: RA-03A-0315 | C45: 449
A46: RA-03A-6046 | C46: 304
A47: RA-03M-2064 | C47: 134
A48: RA-03M-2193 | C48: 106
A49: RA-03S-5013 | C49: 497
A50: RA-03S-5176 | C50: 245
A51: RA-03S-6009A | C51: 139
A52: RA-03S-6025 | C52: 76
A53: RA-03S-6045 | B53: A12-4 | C53: 35
A54: RA-03T-0072 | C54: 496
A55: RA-03T-0076 | B55: S | C55: 360
A56: RA-03T-1992 | C56: 185
A57: RA-03T-3865 | C57: 47
A58: RA-03T-3870 | C58: 32
A59: RA-03V-0054 | C59: 75
A60: RA-03V-0055 | B60: L1-2 | C60: 28
A61: RA-03V-0062 | C61: 0
A62: RA-03V-1639 | C62: 18
A63: RA-03V-1908 | C63: 114
A64: RA-03V-1909 | C64: 40
A65: RA-03V-1991 | C65: 115
A66: RA-04A-1926 | C66: 106
...

Sheet 위치
B1: 품번 | C1: 자재 내역 | D1: 위치 | E1: 입고업체 | F1: 장비
F2: RFS 200 | G2: OCLV
B3: RA-08M-1887 | C3: RA-08M-1887]FRM Bas CEPH (VW) | D3: E4-2 | E3: 주식회사 다유 (10168) | G3: O
B4: RA-08M-2673 | C4: RA-08M-2673]BRK CEPH AXIS BODY (VW) | D4: E2-2 | E4: 주식회사 다유 (10168) | G4: O
B5: RA-08M-2677 | C5: RA-08M-2677]DRUM SCAN CEPH HEADREST (VW) | D5: E2-2 | E5: 주식회사 다유 (10168) | G5: O
B6: RA-08M-2679 | C6: RA-08M-2679]SHAFT CEPH AXIS BODY (VW) | D6: E1-2 | E6: 주식회사 다유 (10168) | G6: O
B7: RA-08M-2705 | C7: RA-08M-2705]BLK CEPH AXIS BODY TOP (VW) | D7: E1-2 | E7: 주식회사 다유 (10168) | G7: O
B8: RA-08M-2707 | C8: RA-08M-2707]BLK CEPH AXIS BODY REAR (VW) | D8: E1-2 | E8: 주식회사 다유 (10168) | G8: O
B9: RA-08A-0612 | C9: RA-08A-0612]ASM _4HEAD Mdl | D9: E1-6 | G9: O
B10: RA-08M-0623 | C10: RA-08M-0623]PIN STOPPER | D10: E2-1 | G10: O
B11: RA-08M-2670 | C11: RA-08M-2670]ARM CEPH BODY (VW) | D11: E4-4 | G11: O
B12: RA-08V-0604 | C12: RA-08V-0604]STOPPER SCAN CEPH | D12: E1-3 | G12: O
B13: RA-08V-0974 | C13: RA-08V-0974]BRK WIRE MOUNT | D13: E1-3 | G13: O
B14: RA-8-15 | C14: RA-8-15]OCL SIGNAL(V) | D14: G3-3 | G14: O
B15: RA-8-16 | C15: RA-8-16]OCL INTERFACE(V) | D15: G2-3 | G15: O
B16: RA-8-17 | C16: RA-8-17]AC POWER OC(V) | D16: G2-3 | G16: O
B17: RA-08T-0176 | D17: 1층 | G17: O
B18: RA-08T-0177 | D18: S | G18: O
B19: RA-08T-2661 | D19: 1층 | G19: O
B20: C16-626ZZ | C20: C16-626ZZ]BALL B-Ring | D20: C1-1 | E20: 플랜피뎀 (10171) | G20: O
B21: C16-MF128ZZS | C21: C16-MF128ZZS]BALL B-Ring | D21: C1-1 | E21: 플랜피뎀 (10171) | G21: O
B22: RA-08M-0625 | C22: RA-08M-0625]_4M CEPH _4HEAD | D22: E2-1 | E22: 플랜피뎀 (10171) | G22: O
B23: RA-08T-0632 | C23: RA-08T-0632]CAS CEPH _4HEAD BAR | D23: S | E23: 플랜피뎀 (10171) | G23: O
B24: RA-08M-0619 | C24: RA-08M-0619]SHAFT _4HEAD FIX | D24: E2-1 | E24: 주식회사 정호기공 (10232) | G24: O
B25: RA-08M-0624 | C25: RA-08M-0624]BLK CEPH _4HEAD | D25: E2-1 | E25: 주식회사 정호기공 (10232) | G25: O
B26: RA-08M-0707 | C26: RA-08M-0707]CAP EARLOD | D26: E1-1 | E26: 주식회사 정호기공 (10232) | G26: O
B27: RA-08M-0708 | C27: RA-08M-0708]RING EARLOD | D27: E1-1 | E27: 주식회사 정호기공 (10232) | G27: O
B28: RA-08M-0738 | C28: RA-08M-0738]BLK OC _4HEAD FIX | D28: E1-2 | E28: 주식회사 정호기공 (10232) | G28: O
B29: RA-08M-0976 | C29: RA-08M-0976]CEPH SCALE BAR | D29: E1-1 | E29: 주식회사 정호기공 (10232) | G29: O
B30: RA-08S-6076 | C30: RA-08S-6076]VIEWORKS, FXRD-1717VA DET | D30: A11-1 | E30: 주식회사 뷰웍스 (10221) | G30: O
B31: RA-08A-0611 | C31: RA-08A-0611]ASM EARLOD Mdl | D31: E1-6 | E31: 주식회사 다유 (10168) | G31: O
... B62: RA-08V-2691 | C62: RA-08V-2691]HLDR CAS CEPH SNSR BOT (VW) | D62: E2-6 | E62: (주)우주정공 (10229) | G62: O
B63: RA-08A-0744 | G63: O
B64: C16-6808ZZ | C64: C16-6808ZZ]BALL B-Ring | D64: 3M1-4 | G64: O
B65: RA-08M-1225 | C65: RA-08M-1225]STRIPPER BOLT ROLLER | D65: E1-1 | G65: O
B66: RA-08M-0622 | C66: RA-08M-0622]WASHER SCAN CEPH | D66: E2-1 | E66: 주식회사 정호기공 (10232) | G66: O
B67: RA-08M-0975 | C67: RA-08M-0975]SHAFT ROLLER AXIS | D67: E1-2 | E67: 주식회사 정호기공 (10232) | G67: O
B68: RA-08T-1466 | C68: RA-08T-1466]CAS CEPH EAR-ROD | D68: S | E68: (주)진광 (10201) | G68: O
B69: RA-08V-2664 | C69: RA-08V-2664]HLDR CAS CEPH SNSR (RL) (VW) | D69: E2-5 | E69: (주)우주정공 (10229) | G69: O
B70: RA-08V-0361 | C70: RA-08V-0361]HLDR CAS CEPH SNSR BACK | D70: L2-3 | E70: (주)우주정공 (10229) | G70: O
...

Sheet 연동데이터
A1: Column1 | B1: Column2 | C1: Column3 | D1: Column4 | E1: Column5 | F1: Column6 | G1: Column7 | H1: Column8 | I1: Column9 | J1: Column10 | K1: Column11 | L1: Column12 | M1: Column13 | N1: Column14 | O1: Column15 | P1: Column16 | Q1: Column17 | R1: Column18 | S1: Column19
A3: ■ 구매자재팀 입출고 현황표
I4: 입고수량 | N4: 출고수량
I5: 445979 | N5: 50622
A6: 입고 | M6: 출고
A7: NO | B7: 구분 | C7: 사급 | D7: NEW | E7: 업체 | F7: 담당자 | G7: 품번 | H7: 품명 | I7: 수량 | J7: REV | K7: 위치 | L7: 일자 | M7: 예약번호 | N7: 출고수량 | O7: 출고일 | P7: 잔여수량
A8: 2445 | B8: 출고재고 | G8: RA-3-3B | H8: RA-3-3B]DCM CONTROL-B | I8: 412 | K8: G2-1 | L8: 46301 | M8: 102930 | N8: 30 | O8: 46297 | P8: 382
A9: 2439 | B9: 출고재고 | G9: RA-06M-0432 | H9: RA-06M-0432]FLANGE TUBE TILT SHAFT B | I9: 259 | K9: H4-1 | L9: 46301 | M9: 102930 | N9: 30 | O9: 46297 | P9: 229
A10: 2436 | B10: 출고재고 | G10: RA-06V-0241 | H10: RA-06V-0241]GUIDE TUBE TILT MICRO SW | I10: 501 | K10: H4-3 | L10: 46301 | M10: 102930 | N10: 30 | O10: 46297 | P10: 471
A11: 2437 | B11: 출고재고 | G11: RA-06V-0242 | H11: RA-06V-0242]BRK TUBE TILT MICRO SW | I11: 317 | K11: H3-3 | L11: 46301 | M11: 102930 | N11: 30 | O11: 46297 | P11: 287
A12: 2438 | B12: 출고재고 | G12: RA-06V-0866 | H12: RA-06V-0866]BRK TUBE TILT MICRO SW | I12: 611 | K12: H3-3 | L12: 46301 | M12: 102930 | N12: 30 | O12: 46297 | P12: 581
A13: 2433 | B13: 출고재고 | G13: RA-06V-3253 | H13: RA-06V-3253]HLDR DC GEARED MOT (M+) | I13: 369 | K13: I2-1 | L13: 46301 | M13: 102930 | N13: 30 | O13: 46297 | P13: 339
A14: 2435 | B14: 출고재고 | G14: RA-06A-5005 | H14: RA-06A-5005]Bd ASSY'-DC MOT Bd | I14: 664 | K14: A3-2, A3-3 | L14: 46301 | M14: 102930 | N14: 30 | O14: 46297 | P14: 634
A15: 2434 | B15: 출고재고 | G15: RA-06S-5091 | H15: RA-06S-5091] DC motor(HDSG56-3448C-615) | I15: 324 | K15: Q | L15: 46301 | M15: 102930 | N15: 30 | O15: 46297 | P15: 294
A16: 2395 | B16: 출고재고 | G16: RA-06M-0243 | H16: RA-06M-0243]BLK TUBE TILT LIMIT | I16: 112 | K16: I3-3 | L16: 46301 | M16: 102930 | N16: 60 | O16: 46297 | P16: 52
A17: 2454 | B17: 출고재고 | G17: RA-06M-0244 | H17: RA-06M-0244]PIN TUBE TILT LIMIT | I17: 334 | K17: I3-3 | L17: 46301 | M17: 102930 | N17: 60 | O17: 46297 | P17: 274
A18: 2455 | B18: 출고재고 | G18: RA-06S-5018 | H18: RA-06S-5018]MICRO SWITCH | I18: 220 | K18: A12-3 | L18: 46301 | M18: 102930 | N18: 60 | O18: 46297 | P18: 160
A19: 2051 | B19: 가용재고 | D19: 입고 | E19: 대영하네스 | F19: 유영국 | G19: RA-3-3B | H19: RA-3-3B]DCM CONTROL-B | I19: 300 | K19: G2-1 | L19: 46296 | P19: 300
A20: 1979 | B20: 가용재고 | D20: 입고 | E20: A&T | F20: 장동은 | G20: RA-06M-0243 | H20: RA-06M-0243]BLK TUBE TILT LIMIT | I20: 300 | K20: I3-3 | L20: 46301 | P20: 300
A21: 1981 | B21: 가용재고 | D21: 입고 | E21: A&T | F21: 장동은 | G21: RA-06M-0244 | H21: RA-06M-0244]PIN TUBE TILT LIMIT | I21: 300 | K21: I3-3 | L21: 46301 | P21: 300
A22: 2030 | B22: 가용재고 | D22: 입고 | E22: 대영하네스 | F22: 유영국 | G22: RA-5-2 | H22: RA-5-2_2]EARTH CEPH | I22: 200 | K22: G4 | L22: 46296 | P22: 200
A23: 1355 | B23: 가용재고 | D23: 입고 | E23: 진광 | F23: 장동은 | G23: RA-03A-0315 | H23: RA-03A-0315]ASM CAS CLMN LWR (L) | I23: 300 | K23: V | L23: 46286 | P23: 300
A24: 1354 | B24: 가용재고 | D24: 입고 | E24: 진광 | F24: 장동은 | G24: RA-03A-0314 | H24: RA-03A-0314]ASM CAS CLMN LWR (R) | I24: 300 | K24: V | L24: 46286 | P24: 300
A25: 1961 | B25: 가용재고 | D25: 입고 | E25: A&T | F25: 장동은 | G25: RA-09A-2754 | H25: RA-09A-2754]ASM CT HEADREST (A+) (VN) | I25: 18 | K25: O3 | L25: 46296 | P25: 18
A26: 1962 | B26: 가용재고 | D26: 입고 | E26: A&T | F26: 장동은 | G26: RA-09A-2754 | H26: RA-09A-2754]ASM CT HEADREST (A+) (VN) | I26: 47 | K26: O3 | L26: 46296 | P26: 47
A27: 1960 | B27: 가용재고 | D27: 입고 | E27: A&T | F27: 장동은 | G27: RA-09A-2754 | H27: RA-09A-2754]ASM CT HEADREST (A+) (VN) | I27: 52 | K27: O3 | L27: 46296 | P27: 52
A28: 2040 | B28: 가용재고 | D28: 입고 | E28: 대영하네스 | F28: 유영국 | G28: RA-5-6 | H28: RA-5-6]EARTH SHAFT TO PC | I28: 250 | K28: G4 | L28: 46296 | P28: 250
A29: 2068 | B29: 가용재고 | D29: 입고 | E29: Bach tung | F29: 유영국 | G29: RA-08M-0623 | H29: RA-08M-0623]PIN STOPPER | I29: 100 | K29: E2-1 | L29: 46302 | P29: 100
A30: 707 | B30: 가용재고 | D30: 기초 | G30: RE-03A-1030 | H30: RE-03A-1030]ASM COLUMN MODULE | I30: 0 | K30: K8 | L30: 46275 | P30: 0
A31: 2627 | B31: 가용재고 | D31: 입고 | E31: A&T | F31: 장동은 | G31: RE-03A-1030 | H31: RE-03A-1030]ASM COLUMN MODULE | I31: 3 | K31: K8 | L31: 46302 | P31: 3
A32: 2015 | B32: 가용재고 | D32: 입고 | E32: Bach tung | F32: 유영국 | G32: RE-05A-0512 | H32: RE-05A-0512]ASM ROTATOR WEIGH | I32: 50 | K32: 4F | L32: 46296 | P32: 50
A33: 1947 | B33: 가용재고 | D33: 입고 | E33: 진광 | F33: 장동은 | G33: RE-01T-0104 | H33: RE-01T-0104]RUBBER CAP DECO | I33: 2000 | K33: W | L33: 46297 | P33: 2000
A34: 1709 | B34: 가용재고 | D34: 입고 | E34: 진광 | F34: 장동은 | G34: RE-09T-0902 | H34: RE-09T-0902]CAS CHINREST LOW | I34: 100 | K34: 3A-22 | L34: 46279 | P34: 100
A35: 1147 | B35: 가용재고 | D35: 입고 | E35: 월드덴탈 | F35: 곽동준 | G35: RA-09S-0389 | H35: RA-09S-0389]CVR BITE BLK VINYL CVR | I35: 455 | K35: L1-1 | L35: 46279 | P35: 455
A36: 1941 | B36: 가용재고 | D36: 입고 | E36: 진광 | F36: 장동은 | G36: RE-02T-0247 | H36: RE-02T-0247]CAS VERT TOP | I36: 50 | K36: 3A-14 | L36: 46296 | P36: 50
A37: 1359 | B37: 가용재고 | D37: 입고 | E37: 진광 | F37: 장동은 | G37: RE-04T-0453 | H37: RE-04T-0453]CAP HANDLE B | I37: 80 | K37: 3L14-2 | L37: 46286 | P37: 80
A38: 1360 | B38: 가용재고 | D38: 입고 | E38: 진광 | F38: 장동은 | G38: RE-04T-0453 | H38: RE-04T-0453]CAP HANDLE B | I38: 300 | K38: 3L14-2 | L38: 46286 | P38: 300
A39: 316 | B39: 가용재고 | D39: 기초 | G39: RA-02A-2740 | H39: RA-02A-2740]ASM VERT TOTAL (A+) (VN) | I39: 0 | K39: P | L39: 46253 | P39: 0
A40: 170 | B40: 가용재고 | D40: 기초 | G40: RA-08M-2677 | H40: RA-08M-2677]DRUM SCAN CEPH HEADREST (VW) | I40: 0 | K40: E2-2 | L40: 46232 | P40: 0
A41: 171 | B41: 가용재고 | D41: 기초 | G41: RA-08M-2679 | H41: RA-08M-2679]SHAFT CEPH AXIS BODY (VW) | I41: 0 | K41: E1-2 | L41: 46232 | P41: 0
...

Sheet 입출고현황
B2: ■ 구매자재팀 입출고 현황표
J3: 입고수량 | P3: 출고수량
J4: =IFERROR(INDEX(입출고현황[Column9],4),0) -> 445979 | P4: =IFERROR(IF(INDEX(입출고현황[#All],7,13)="담당자",INDEX(입출고현황[Column15],4),INDEX(입출고현황[Column14],4)),0) -> 50622
B5: 입고 | N5: 출고
B6: NO | C6: 구분 | D6: 사급 | E6: NEW | F6: 업체 | G6: 담당자 | H6: 품번 | I6: 품명 | J6: 수량 | K6: REV | L6: 위치 | M6: 일자 | N6: 담당자 | O6: 예약번호 | P6: 출고수량 | Q6: 출고일 | R6: 잔여수량
B7: {=_xlfn.LET(_xlpm.t,입출고현황[#All],_xlpm.o,INDEX(_xlpm.t,7,13)="담당자",_xlpm.d,_xlfn.DROP(_xlpm.t,7),_xlpm.x,IF(_xlpm.o,_xlfn.TAKE(_xlpm.d,,17),_xlfn.LET(_xlpm.y,_xlfn.TAKE(_xlpm.d,,16),_xlfn.HSTACK(_xlfn.TAKE(_xlpm.y,,12),IF(_xlfn.SEQUENCE(ROWS(_xlpm.y))>0,"",""),_xlfn.DROP(_xlpm.y,,12)))),_xlpm.k,_xlfn.SEQUENCE(,COLUMNS(_xlpm.x)),IF((_xlpm.x=0)*(_xlpm.k<>9)*(_xlpm.k<>17)*(((_xlpm.k<>15)+(_xlpm.k=15)*(INDEX(_xlpm.x,,14)=0))>0),"",_xlpm.x))} -> 2445 | C7: 출고재고 | H7: RA-3-3B | I7: RA-3-3B]DCM CONTROL-B | J7: 412 | L7: G2-1 | M7: 46301 | O7: 102930 | P7: 30 | Q7: 46297 | R7: 382
B8: 2439 | C8: 출고재고 | H8: RA-06M-0432 | I8: RA-06M-0432]FLANGE TUBE TILT SHAFT B | J8: 259 | L8: H4-1 | M8: 46301 | O8: 102930 | P8: 30 | Q8: 46297 | R8: 229
B9: 2436 | C9: 출고재고 | H9: RA-06V-0241 | I9: RA-06V-0241]GUIDE TUBE TILT MICRO SW | J9: 501 | L9: H4-3 | M9: 46301 | O9: 102930 | P9: 30 | Q9: 46297 | R9: 471
B10: 2437 | C10: 출고재고 | H10: RA-06V-0242 | I10: RA-06V-0242]BRK TUBE TILT MICRO SW | J10: 317 | L10: H3-3 | M10: 46301 | O10: 102930 | P10: 30 | Q10: 46297 | R10: 287
B11: 2438 | C11: 출고재고 | H11: RA-06V-0866 | I11: RA-06V-0866]BRK TUBE TILT MICRO SW | J11: 611 | L11: H3-3 | M11: 46301 | O11: 102930 | P11: 30 | Q11: 46297 | R11: 581
B12: 2433 | C12: 출고재고 | H12: RA-06V-3253 | I12: RA-06V-3253]HLDR DC GEARED MOT (M+) | J12: 369 | L12: I2-1 | M12: 46301 | O12: 102930 | P12: 30 | Q12: 46297 | R12: 339
B13: 2435 | C13: 출고재고 | H13: RA-06A-5005 | I13: RA-06A-5005]Bd ASSY'-DC MOT Bd | J13: 664 | L13: A3-2, A3-3 | M13: 46301 | O13: 102930 | P13: 30 | Q13: 46297 | R13: 634
B14: 2434 | C14: 출고재고 | H14: RA-06S-5091 | I14: RA-06S-5091] DC motor(HDSG56-3448C-615) | J14: 324 | L14: Q | M14: 46301 | O14: 102930 | P14: 30 | Q14: 46297 | R14: 294
B15: 2395 | C15: 출고재고 | H15: RA-06M-0243 | I15: RA-06M-0243]BLK TUBE TILT LIMIT | J15: 112 | L15: I3-3 | M15: 46301 | O15: 102930 | P15: 60 | Q15: 46297 | R15: 52
B16: 2454 | C16: 출고재고 | H16: RA-06M-0244 | I16: RA-06M-0244]PIN TUBE TILT LIMIT | J16: 334 | L16: I3-3 | M16: 46301 | O16: 102930 | P16: 60 | Q16: 46297 | R16: 274
B17: 2455 | C17: 출고재고 | H17: RA-06S-5018 | I17: RA-06S-5018]MICRO SWITCH | J17: 220 | L17: A12-3 | M17: 46301 | O17: 102930 | P17: 60 | Q17: 46297 | R17: 160
B18: 2051 | C18: 가용재고 | E18: 입고 | F18: 대영하네스 | G18: 유영국 | H18: RA-3-3B | I18: RA-3-3B]DCM CONTROL-B | J18: 300 | L18: G2-1 | M18: 46296 | R18: 300
B19: 1979 | C19: 가용재고 | E19: 입고 | F19: A&T | G19: 장동은 | H19: RA-06M-0243 | I19: RA-06M-0243]BLK TUBE TILT LIMIT | J19: 300 | L19: I3-3 | M19: 46301 | R19: 300
B20: 1981 | C20: 가용재고 | E20: 입고 | F20: A&T | G20: 장동은 | H20: RA-06M-0244 | I20: RA-06M-0244]PIN TUBE TILT LIMIT | J20: 300 | L20: I3-3 | M20: 46301 | R20: 300
B21: 2030 | C21: 가용재고 | E21: 입고 | F21: 대영하네스 | G21: 유영국 | H21: RA-5-2 | I21: RA-5-2_2]EARTH CEPH | J21: 200 | L21: G4 | M21: 46296 | R21: 200
B22: 1355 | C22: 가용재고 | E22: 입고 | F22: 진광 | G22: 장동은 | H22: RA-03A-0315 | I22: RA-03A-0315]ASM CAS CLMN LWR (L) | J22: 300 | L22: V | M22: 46286 | R22: 300
B23: 1354 | C23: 가용재고 | E23: 입고 | F23: 진광 | G23: 장동은 | H23: RA-03A-0314 | I23: RA-03A-0314]ASM CAS CLMN LWR (R) | J23: 300 | L23: V | M23: 46286 | R23: 300
B24: 1961 | C24: 가용재고 | E24: 입고 | F24: A&T | G24: 장동은 | H24: RA-09A-2754 | I24: RA-09A-2754]ASM CT HEADREST (A+) (VN) | J24: 18 | L24: O3 | M24: 46296 | R24: 18
B25: 1962 | C25: 가용재고 | E25: 입고 | F25: A&T | G25: 장동은 | H25: RA-09A-2754 | I25: RA-09A-2754]ASM CT HEADREST (A+) (VN) | J25: 47 | L25: O3 | M25: 46296 | R25: 47
B26: 1960 | C26: 가용재고 | E26: 입고 | F26: A&T | G26: 장동은 | H26: RA-09A-2754 | I26: RA-09A-2754]ASM CT HEADREST (A+) (VN) | J26: 52 | L26: O3 | M26: 46296 | R26: 52
B27: 2040 | C27: 가용재고 | E27: 입고 | F27: 대영하네스 | G27: 유영국 | H27: RA-5-6 | I27: RA-5-6]EARTH SHAFT TO PC | J27: 250 | L27: G4 | M27: 46296 | R27: 250
B28: 2068 | C28: 가용재고 | E28: 입고 | F28: Bach tung | G28: 유영국 | H28: RA-08M-0623 | I28: RA-08M-0623]PIN STOPPER | J28: 100 | L28: E2-1 | M28: 46302 | R28: 100
B29: 707 | C29: 가용재고 | E29: 기초 | H29: RE-03A-1030 | I29: RE-03A-1030]ASM COLUMN MODULE | J29: 0 | L29: K8 | M29: 46275 | R29: 0
B30: 2627 | C30: 가용재고 | E30: 입고 | F30: A&T | G30: 장동은 | H30: RE-03A-1030 | I30: RE-03A-1030]ASM COLUMN MODULE | J30: 3 | L30: K8 | M30: 46302 | R30: 3
B31: 2015 | C31: 가용재고 | E31: 입고 | F31: Bach tung | G31: 유영국 | H31: RE-05A-0512 | I31: RE-05A-0512]ASM ROTATOR WEIGH | J31: 50 | L31: 4F | M31: 46296 | R31: 50
B32: 1947 | C32: 가용재고 | E32: 입고 | F32: 진광 | G32: 장동은 | H32: RE-01T-0104 | I32: RE-01T-0104]RUBBER CAP DECO | J32: 2000 | L32: W | M32: 46297 | R32: 2000
B33: 1709 | C33: 가용재고 | E33: 입고 | F33: 진광 | G33: 장동은 | H33: RE-09T-0902 | I33: RE-09T-0902]CAS CHINREST LOW | J33: 100 | L33: 3A-22 | M33: 46279 | R33: 100
B34: 1147 | C34: 가용재고 | E34: 입고 | F34: 월드덴탈 | G34: 곽동준 | H34: RA-09S-0389 | I34: RA-09S-0389]CVR BITE BLK VINYL CVR | J34: 455 | L34: L1-1 | M34: 46279 | R34: 455
B35: 1941 | C35: 가용재고 | E35: 입고 | F35: 진광 | G35: 장동은 | H35: RE-02T-0247 | I35: RE-02T-0247]CAS VERT TOP | J35: 50 | L35: 3A-14 | M35: 46296 | R35: 50
B36: 1359 | C36: 가용재고 | E36: 입고 | F36: 진광 | G36: 장동은 | H36: RE-04T-0453 | I36: RE-04T-0453]CAP HANDLE B | J36: 80 | L36: 3L14-2 | M36: 46286 | R36: 80
B37: 1360 | C37: 가용재고 | E37: 입고 | F37: 진광 | G37: 장동은 | H37: RE-04T-0453 | I37: RE-04T-0453]CAP HANDLE B | J37: 300 | L37: 3L14-2 | M37: 46286 | R37: 300
B38: 316 | C38: 가용재고 | E38: 기초 | H38: RA-02A-2740 | I38: RA-02A-2740]ASM VERT TOTAL (A+) (VN) | J38: 0 | L38: P | M38: 46253 | R38: 0
B39: 170 | C39: 가용재고 | E39: 기초 | H39: RA-08M-2677 | I39: RA-08M-2677]DRUM SCAN CEPH HEADREST (VW) | J39: 0 | L39: E2-2 | M39: 46232 | R39: 0
B40: 171 | C40: 가용재고 | E40: 기초 | H40: RA-08M-2679 | I40: RA-08M-2679]SHAFT CEPH AXIS BODY (VW) | J40: 0 | L40: E1-2 | M40: 46232 | R40: 0
B41: 172 | C41: 가용재고 | E41: 기초 | H41: RA-08M-2705 | I41: RA-08M-2705]BLK CEPH AXIS BODY TOP (VW) | J41: 0 | L41: E1-2 | M41: 46232 | R41: 0
...

Sheet 리스트
B2: 구분 | C2: 품번 | D2: 비고
B3: 3D(VERTICAL, ROTATOR) | C3: RA-10-2 | E3: 2순위재고실사
B4: 3D(VERTICAL, ROTATOR) | C4: RA-05V-2651 | E4: 2순위재고실사
B5: 3D(VERTICAL, ROTATOR) | C5: RA-05V-0513 | E5: 2순위재고실사
B6: 3D(VERTICAL, ROTATOR) | C6: RA-05V-2653 | E6: 2순위재고실사
B7: 3D(VERTICAL, ROTATOR) | C7: RA-05M-2907 | D7: 파렛트화 | E7: 1순위 재고실사
B8: 3D(VERTICAL, ROTATOR) | C8: RA-02A-2741 | D8: 파렛트화 | E8: 1순위 재고실사
B9: 3D(VERTICAL, ROTATOR) | C9: RA-05A-2721 | D9: 파렛트화 | E9: 1순위 재고실사
B10: 3D(VERTICAL, ROTATOR) | C10: RA-05V-0501 | E10: 2순위재고실사
B11: 3D(VERTICAL, ROTATOR) | C11: RA-05A-6112 | E11: 2순위재고실사

Sheet 입고 프로세스
B2: *현 프로세스를 진행시 실물과 전산과 엑셀파일은 항시 같이 완료 되어야 하며
B3: 각 진행 업무가 끝나면 다른 업무를 지원 또는 진행 해야 합니다.
B5: [입고 프로세스]
B6: 1. 업체로부터 입고품 인수
B7: - 거래명세서 및 실물 수량 확인
B8: - 모든 자재들은 거래명세서가 실물전달시 같이 전달 되어야 하며
B9: 실물과 전달이 안된다면, 실물 도착전 메일상으로 전달 받아야함
B11: 2. 입고자재 품질팀 전달
B12: - 실물 품질팀 전달 및 SAP 입고 진행
B13: - 검사품목이 아닌 경우 SL01로 입고를 잡거나,
B14: SL11로 입고를 잡고 바로 SL01로 이동전기 진행
B16: 3. 검사 완료품 지정 장소로 실물 이동
... B26: - SAP 이동전기 진행 및 입출고 현황파일에 출고내역 작성

Sheet Sheet1
C2: 기준 | E2: 출고
C3: C16-626ZZ | E3: C16-626ZZ | F3: =C3=E3 -> TRUE
C4: C16-6808ZZ | E4: C16-6808ZZ | F4: =C4=E4 -> TRUE
C5: C16-MF128ZZS | E5: C16-MF128ZZS | F5: =C5=E5 -> TRUE
C6: RA-04S-0977 | E6: RA-04S-0977 | F6: =C6=E6 -> TRUE
C7: RA-06V-1509 | E7: RA-06V-1509 | F7: =C7=E7 -> TRUE
C8: RA-08A-0611 | E8: RA-08A-0611 | F8: =C8=E8 -> TRUE
C9: RA-08A-0612 | E9: RA-08A-0612 | F9: =C9=E9 -> TRUE
E10: RA-08A-0744 | F10: =C10=E10 -> FALSE
C11: RA-08A-0745 | E11: RA-08A-0745 | F11: =C11=E11 -> TRUE
C12: RA-08M-0619 | E12: RA-08M-0619 | F12: =C12=E12 -> TRUE
C13: RA-08M-0620 | E13: RA-08M-0620 | F13: =C13=E13 -> TRUE
C14: RA-08M-0622 | E14: RA-08M-0622 | F14: =C14=E14 -> TRUE
C15: RA-08M-0623 | E15: RA-08M-0623 | F15: =C15=E15 -> TRUE
C16: RA-08M-0624 | E16: RA-08M-0624 | F16: =C16=E16 -> TRUE
C17: RA-08M-0625 | E17: RA-08M-0625 | F17: =C17=E17 -> TRUE
C18: RA-08M-0707 | E18: RA-08M-0707 | F18: =C18=E18 -> TRUE
C19: RA-08M-0708 | E19: RA-08M-0708 | F19: =C19=E19 -> TRUE
C20: RA-08M-0738 | E20: RA-08M-0738 | F20: =C20=E20 -> TRUE
C21: RA-08M-0975 | E21: RA-08M-0975 | F21: =C21=E21 -> TRUE
C22: RA-08M-0976 | E22: RA-08M-0976 | F22: =C22=E22 -> TRUE
... C71: RA-9-12 | E71: RA-9-12 | F71: =C71=E71 -> TRUE
